Workbook

Sheet ReadMe
A1: Tên Đồ Án: | B1: HỆ THỐNG NUÔI THÚ CƯNG ẢO ĐỒNG HÀNH NĂNG SUẤT VĂN PHÒNG (OFFICEPET - PTUD_NUOITHU)
A3: Nhóm Thực Hiện: | B3: NHÓM SINH VIÊN THỰC HIỆN ĐỀ TÀI PHÁT TRIỂN ỨNG DỤNG
A4: Thành viên 1 (Nhóm trưởng): | B4: Nguyễn Đỉnh - MSSV: 123000431 (Phụ trách: Auth, Desktop PiP, Admin Console, Security & NFR)
A5: Thành viên 2: | B5: Hồ Tâm Phi Hùng - MSSV: 123000287 (Phụ trách: Nuôi thú 11 hoạt ảnh, Nhiệm vụ, Shop & Kho đồ)
A6: Thành viên 3: | B6: Võ Lê Hoàng Nhã - MSSV: 123000311 (Phụ trách: Pomodoro, Wellness Lofi/Thở, Chatbot AI, Vườn chung)
A7: Học Phần: | B7: Phát triển Ứng dụng (PTUD) - Đề tài Hệ thống Nuôi Thú Cưng Văn Phòng
A8: Phiên bản Hệ thống: | B8: Release v1.0.0 (Chuẩn hóa 11 Hoạt ảnh Thú Cưng & Kiến trúc Tương thích ngược)
A9: Ngày lập Kế hoạch: | B9: 24/10/2026
A10: Bản quyền Đề tài: | B10: OfficePet System - PTUD_NuoiThu © 2026
A11: Quy Ước Iteration: | B11: Iteration 1: Smoke Test các luồng Critical Iteration 2: Kiểm thử Core Features (Auth, Nuôi thú, Pomodoro, Admin Forge) Iteration 3: Kiểm thử toàn diện chức năng (Full Functional: Shop, Vườn chung, Bạn bè, AI Chat) Iteration 4: Kiểm thử Hồi quy & Phi chức năng (Regression, Tương thích thú cũ 17 hàng, Canvas 60fps, Bảo mật) Iteration 5: Nghiệm thu toàn diện trước bàn giao (Final Acceptance / UAT)
A12: Quy Chuẩn Tài Liệu: | B12: Kế hoạch kiểm thử phân kỳ (Test Plan Iterations Template) chuẩn mực theo yêu cầu của Giảng viên hướng dẫn.
A13: Phạm Vi Nghiệp Vụ: | B13: Bao phủ toàn diện 10 Phân hệ chức năng & phi chức năng (TS01 -> TS10) với 25 kịch bản tích hợp và 5 Vòng lặp kiểm thử (Iterations).
... A27: • N/A: | B27: Test case không nằm trong phạm vi kế hoạch thực thi của đợt Iteration này.

Sheet Test Case List
A1: Scenario ID | B1: Scenario | C1: Test Case ID | D1: Test Case Name | E1: Test Case Description | F1: Status | G1: Owner | H1: Approver(s) | I1: Comments | J1: Use Case(s) | K1: Functional Requirement(s) | L1: Classification A | M1: Classification B
A2: TS01 | B2: Xác thực & Tài khoản | C2: TC1.1 | D2: Đăng ký tài khoản mới hợp lệ & Kiểm thực lỗi email/mật khẩu | E2: [Mục đích] Xác nhận quy trình đăng ký tài khoản nhân viên mới vào hệ thống. [Điều kiện] Người dùng chưa có tài khoản, đang ở màn hình Đăng ký. [Các bước] 1. Nhập Họ tên 'Nguyễn Văn A', Email hợp lệ, Mật khẩu >= 8 ký tự, chọn Phòng ban. 2. Nhấn nút 'Đăng ký'. 3. Thử lại với email trùng hoặc mật khẩu < 8 ký tự. [Kỳ vọng] Hệ thống tạo tài khoản mã hóa bcrypt, báo thành công; chặn email trùng và mật khẩu yếu. | F2: Approved | G2: Nguyễn Đỉnh (123000431) | H2: Nguyễn Đỉnh (123000431) - Lead QA | J2: UC-01 | K2: FR-01.1, FR-01.2 | L2: Critical | M2: P1 - High
A3: TS01 | B3: Xác thực & Tài khoản | C3: TC1.2 | D3: Đăng nhập phân quyền vai trò (Role ADMIN & USER) và JWT Token | E3: [Mục đích] Xác thực cơ chế phân quyền truy cập giữa Quản trị viên và Nhân viên. [Điều kiện] Đã có sẵn tài khoản Admin và User trong hệ thống. [Các bước] 1. Đăng nhập User -> điều hướng vào Vườn thú cưng làm việc. 2. Đăng xuất tài khoản. 3. Đăng nhập Admin -> hiển thị menu Bảng điều khiển Quản trị (Admin Console). [Kỳ vọng] JWT token cấp đúng role; User bị chặn vào /admin, Admin truy cập được trang quản trị. | F3: Approved | G3: Nguyễn Đỉnh (123000431) | H3: Nguyễn Đỉnh (123000431) - Lead QA | J3: UC-01 | K3: FR-01.3, FR-01.4 | L3: Critical | M3: P1 - High
A4: TS01 | B4: Xác thực & Tài khoản | C4: TC1.3 | D4: Quên mật khẩu qua mã OTP Email & Cập nhật ảnh đại diện Avatar | E4: [Mục đích] Kiểm tra quy trình khôi phục mật khẩu qua OTP và cập nhật thông tin cá nhân. [Điều kiện] Tài khoản người dùng có email hợp lệ. [Các bước] 1. Bấm 'Quên mật khẩu', nhập email nhận mã OTP 6 chữ số. 2. Nhập mã OTP và thiết lập mật khẩu mới. 3. Đăng nhập đổi ảnh đại diện trong trang Hồ sơ cá nhân. [Kỳ vọng] OTP gửi thành công; cập nhật mật khẩu và avatar hiển thị tức thì trên giao diện. | F4: Approved | G4: Nguyễn Đỉnh (123000431) | H4: Nguyễn Đỉnh (123000431) - Lead QA | J4: UC-01 | K4: FR-01.5, FR-01.6 | L4: Major | M4: P2 - Medium | O4: cột A-B: major, minor, critical
A5: TS02 | B5: Nuôi & Chăm sóc Thú Cưng | C5: TC2.1 | D5: Khởi tạo nhận nuôi thú cưng & Cơ chế suy giảm chỉ số sinh học tự nhiên | E5: [Mục đích] Xác thực nhận nuôi thú cưng ban đầu và suy giảm chỉ số Đói/Khát/Năng lượng theo thời gian. [Điều kiện] Tài khoản mới đăng nhập lần đầu vào hệ thống. [Các bước] 1. Chọn thú cưng mặc định (Corgi), đặt tên 'Bắp Cải', nhận nuôi. 2. Quan sát chỉ số Đói và Khát giảm dần sau mỗi chu kỳ 5-10 phút. [Kỳ vọng] Bản ghi UserPet tạo đúng Level 1, 100 Năng lượng, 80 Đói/Khát; thanh trạng thái đổi màu vàng/đỏ khi < 30%. | F5: Approved | G5: Hồ Tâm Phi Hùng (123000287) | H5: Nguyễn Đỉnh (123000431) - Lead QA | J5: UC-02 | K5: FR-02.1, FR-02.2 | L5: Critical | M5: P1 - High
A6: TS02 | B6: Nuôi & Chăm sóc Thú Cưng | C6: TC2.2 | D6: Hành động Cho ăn (EATING) và Cho uống nước (DRINKING) tách bạch | E6: [Mục đích] Kiểm tra hoạt ảnh chuẩn hóa riêng biệt giữa Ăn và Uống theo chuẩn 11 hoạt ảnh mới. [Điều kiện] Thú cưng có chỉ số Đói < 80 và Khát < 80. [Các bước] 1. Nhấn nút 'Cho ăn' -> quan sát hoạt ảnh EATING. 2. Nhấn nút 'Cho uống nước' -> quan sát hoạt ảnh DRINKING tách biệt riêng. [Kỳ vọng] Cho ăn hồi +30 Đói với hoạt ảnh nhai thức ăn; Cho uống hồi +25 Khát với hoạt ảnh uống nước riêng; kết thúc trở về IDLE. | F6: Approved | G6: Hồ Tâm Phi Hùng (123000287) | H6: Nguyễn Đỉnh (123000431) - Lead QA | J6: UC-02 | K6: FR-02.3, FR-02.4 | L6: Critical | M6: P1 - High
A7: TS02 | B7: Nuôi & Chăm sóc Thú Cưng | C7: TC2.3 | D7: Tương tác vuốt ve (PETTING) giới hạn +30 EXP/ngày và Hoạt ảnh HAPPY / SAD | E7: [Mục đích] Kiểm tra tương tác vuốt ve, cơ chế chống spam cày cấp và chuyển đổi hoạt ảnh cảm xúc. [Điều kiện] Thú cưng đang đứng yên ở trạng thái IDLE. [Các bước] 1. Click chuột vuốt ve thú cưng liên tục 6 lần (+5 EXP/lần). 2. Click tiếp tục lần 7 trở đi trong ngày. 3. Để chỉ số đói khát tụt xuống < 15%. [Kỳ vọng] Thú cưng phát tim (PETTING), cộng tối đa +30 EXP/ngày; click tiếp vẫn vui nhưng không cộng thêm EXP; khi đói hiển thị HUNGRY/SAD. | F7: Approved | G7: Hồ Tâm Phi Hùng (123000287) | H7: Nguyễn Đỉnh (123000431) - Lead QA | J7: UC-02 | K7: FR-02.5, FR-02.6 | L7: Major | M7: P2 - Medium
A8: TS02 | B8: Nuôi & Chăm sóc Thú Cưng | C8: TC2.4 | D8: Cho thú cưng ngủ (SLEEPING) hồi năng lượng và Thăng cấp thú cưng | E8: [Mục đích] Kiểm tra cơ chế hồi phục năng lượng khi ngủ và thăng cấp (Level Up). [Điều kiện] Năng lượng < 50, điểm kinh nghiệm đạt 95/100 EXP. [Các bước] 1. Bấm 'Đi ngủ' -> phòng tối, hoạt ảnh SLEEPING phập phồng chữ Zzz. 2. Bấm 'Đánh thức'. 3. Thực hiện hành động chăm sóc để đạt mốc 100 EXP. [Kỳ vọng] Năng lượng tăng dần khi ngủ; khi đạt 100 EXP kích hoạt Level Up, hoạt ảnh nhảy múa DANCING và nhận thưởng mở khóa. | F8: Approved | G8: Hồ Tâm Phi Hùng (123000287) | H8: Nguyễn Đỉnh (123000431) - Lead QA | J8: UC-02 | K8: FR-02.7, FR-02.8 | L8: Major | M8: P2 - Medium
A9: TS03 | B9: Desktop Companion & PiP | C9: TC3.1 | D9: Thu nhỏ thú cưng ra màn hình Desktop (PiP) và Kéo thả ghi nhớ tọa độ | E9: [Mục đích] Kiểm tra tính năng Document PiP luôn nổi trên desktop và ghi nhớ tọa độ màn hình. [Điều kiện] Trình duyệt có hỗ trợ Document PiP API. [Các bước] 1. Nhấn nút Desktop PiP trên web. 2. Kéo thả thú cưng sang góc phải dưới màn hình. 3. Đóng cửa sổ và mở lại PiP. [Kỳ vọng] Cửa sổ popup trong suốt nổi trên màn hình; khi mở lại tự động khôi phục đúng tọa độ đã kéo thả trước đó. | F9: Approved | G9: Nguyễn Đỉnh (123000431) | H9: Nguyễn Đỉnh (123000431) - Lead QA | J9: UC-03 | K9: FR-03.1, FR-03.2 | L9: Major | M9: P2 - Medium
A10: TS03 | B10: Desktop Companion & PiP | C10: TC3.2 | D10: Thú cưng tự do đi lại trong ranh giới (Roaming) và Menu thao tác nhanh | E10: [Mục đích] Kiểm tra chuyển động đi bộ tự nhiên và bảng menu chuột phải trên desktop. [Điều kiện] Cửa sổ Desktop PiP đang mở. [Các bước] 1. Bật chế độ Roaming, quan sát thú đi dạo. 2. Nhấp chuột phải (Right-click) lên thú cưng. 3. Chọn nút 'Cho ăn nhanh'. [Kỳ vọng] Thú cưng tự động quay đầu khi chạm mép màn hình (WALKING); menu chuột phải hiển thị mượt mà và thực hiện hành động tức thì. | F10: Approved | G10: Nguyễn Đỉnh (123000431) | H10: Nguyễn Đỉnh (123000431) - Lead QA | J10: UC-03 | K10: FR-03.3, FR-03.4 | L10: Minor | M10: P3 - Low
A11: TS04 | B11: Pomodoro & Năng suất | C11: TC4.1 | D11: Phiên Pomodoro 25 phút, thú cưng gõ phím TYPING và Nhận thưởng hoàn thành | E11: [Mục đích] Kiểm tra đồng hồ đếm giờ Pomodoro, đồng bộ trạng thái gõ phím và cộng thưởng hoàn thành. [Điều kiện] Thú cưng đang ở trạng thái IDLE. [Các bước] 1. Bắt đầu phiên 25 phút -> quan sát thú chuyển sang TYPING. 2. Tạm dừng -> trở về IDLE. 3. Để đếm hết 25 phút. [Kỳ vọng] Đồng hồ chạy chuẩn xác; thú cưng ngồi gõ máy tính chăm chỉ; kết thúc phiên nhận +50 EXP, +20 Vàng và phát chuông báo. | F11: Approved | G11: Võ Lê Hoàng Nhã (123000311) | H11: Nguyễn Đỉnh (123000431) - Lead QA | J11: UC-04 | K11: FR-04.1, FR-04.2 | L11: Critical | M11: P1 - High
A12: TS04 | B12: Pomodoro & Năng suất | C12: TC4.2 | D12: Chế độ Nghiêm khắc cảnh báo xao nhãng khi người dùng rời tab làm việc | E12: [Mục đích] Kiểm tra tính năng chống xao nhãng của Pomodoro trong giờ làm việc. [Điều kiện] Bật 'Chế độ Nghiêm khắc' (Strict Mode) trong cài đặt Pomodoro. [Các bước] 1. Bắt đầu phiên làm việc. 2. Chuyển sang tab khác (Youtube/MXH) hơn 15 giây. 3. Quay trở lại ứng dụng. [Kỳ vọng] Trình duyệt gửi thông báo đẩy nhắc nhở tập trung; thú cưng chuyển vẻ mặt buồn (SAD) cảnh báo người dùng. | F12: Approved | G12: Võ Lê Hoàng Nhã (123000311) | H12: Nguyễn Đỉnh (123000431) - Lead QA | J12: UC-04 | K12: FR-04.3 | L12: Major | M12: P2 - Medium
A13: TS04 | B13: Pomodoro & Năng suất | C13: TC4.3 | D13: Thực hiện Bài tập thở thư giãn (4-7-8 / Box) và Trình phát nhạc Lofi | E13: [Mục đích] Kiểm tra các tính năng chăm sóc sức khỏe tinh thần và phát nhạc nền tập trung. [Điều kiện] Thiết bị có loa / tai nghe kết nối hoạt động. [Các bước] 1. Chọn kỹ thuật thở 4-7-8, làm theo nhịp thở trực quan trên màn hình. 2. Bật trình phát nhạc Lofi, chỉnh âm lượng, chuyển sang track tiếng mưa. [Kỳ vọng] Đồ họa vòng tròn thở co giãn đúng nhịp giây; nhạc Lofi phát êm ái, chuyển bài mượt mà không lỗi âm thanh. | F13: Approved | G13: Võ Lê Hoàng Nhã (123000311) | H13: Nguyễn Đỉnh (123000431) - Lead QA | J13: UC-04 | K13: FR-04.4, FR-04.5 | L13: Major | M13: P2 - Medium
A14: TS05 | B14: Chatbot AI Đồng hành | C14: TC5.1 | D14: Hộp thoại Chatbot AI, gửi câu hỏi công việc và Nhận phản hồi thông minh | E14: [Mục đích] Kiểm tra giao diện ngăn kéo chat và phản hồi thông minh từ trợ lý AI. [Điều kiện] Kết nối Internet hoạt động, API Key được cấu hình. [Các bước] 1. Mở ngăn kéo chat bên cạnh thú cưng. 2. Nhập câu hỏi xin lời khuyên sắp xếp công việc. 3. Nhấn gửi tin nhắn. [Kỳ vọng] Tin nhắn hiển thị đẹp mắt, thú cưng hiển thị bong bóng suy nghĩ và trả lời động viên khoa học trong 1-3 giây. | F14: Approved | G14: Võ Lê Hoàng Nhã (123000311) | H14: Nguyễn Đỉnh (123000431) - Lead QA | J14: UC-05 | K14: FR-05.1, FR-05.2 | L14: Major | M14: P2 - Medium
A15: TS05 | B15: Chatbot AI Đồng hành | C15: TC5.2 | D15: Đồng bộ hoạt ảnh biểu cảm thú cưng (HAPPY / SAD) theo sắc thái trò chuyện | E15: [Mục đích] Kiểm tra sự gắn kết cảm xúc giữa nội dung trò chuyện AI và hoạt ảnh thú cưng. [Điều kiện] Chatbot AI đang hoạt động bình thường. [Các bước] 1. Gửi tin nhắn khoe tin vui hoàn thành dự án -> quan sát thú cưng. 2. Gửi tin nhắn tâm sự chuyện buồn áp lực -> quan sát thú cưng. [Kỳ vọng] Với tin vui thú cưng kích hoạt HAPPY / DANCING; với chuyện buồn thú làm động tác vẫy tay chia sẻ an ủi. | F15: Approved | G15: Võ Lê Hoàng Nhã (123000311) | H15: Nguyễn Đỉnh (123000431) - Lead QA | J15: UC-05 | K15: FR-05.3 | L15: Minor | M15: P3 - Low
A16: TS06 | B16: Nhiệm vụ & Thi đua | C16: TC6.1 | D16: Nhiệm vụ hàng ngày, tự động cộng dồn tiến độ và Nhận thưởng EXP | E16: [Mục đích] Kiểm tra hệ thống tự động ghi nhận hành vi người dùng vào tiến độ nhiệm vụ. [Điều kiện] Nhiệm vụ 'Cho ăn 3 lần' đang có tiến độ 0/3. [Các bước] 1. Thực hiện cho thú ăn đủ 3 lần. 2. Mở tab Nhiệm vụ kiểm tra tiến độ. 3. Bấm nút 'Nhận thưởng'. [Kỳ vọng] Thanh tiến trình tự động nhảy 3/3; nút 'Nhận thưởng' sáng lên; bấm nhận cộng đúng EXP và nút chuyển sang 'Đã nhận'. | F16: Approved | G16: Hồ Tâm Phi Hùng (123000287) | H16: Nguyễn Đỉnh (123000431) - Lead QA | J16: UC-06 | K16: FR-06.1, FR-06.2 | L16: Critical | M16: P1 - High
... A26: TS10 | B26: Phi Chức Năng & Bảo Mật | C26: TC10.2 | D26: Render Canvas 60 FPS không rò rỉ RAM, Chặn Route Guard /admin và Chống XSS | E26: [Mục đích] Kiểm tra hiệu năng mượt mà của Canvas và kiểm thử an toàn bảo mật hệ thống. [Điều kiện] Đăng nhập bằng tài khoản User thông thường. [Các bước] 1. Đo FPS khi thú cưng chuyển động trong 30 phút. 2. Nhập URL /admin/pets trên trình duyệt. 3. Thử inject payload <script>alert(1)</script> vào tên thú. [Kỳ vọng] FPS đạt 55-60 FPS ổn định, RAM không phình; route /admin bị chặn 403; payload XSS bị escape an toàn. | F26: Approved | G26: Nguyễn Đỉnh (123000431) | H26: Nguyễn Đỉnh (123000431) - Lead QA | J26: UC-10 | K26: FR-10.3, FR-10.4, FR-10.5 | L26: Critical | M26: P1 - High
A27: Insert lines above here only | B27: Phi Chức Năng & Bảo Mật | C27: TC10.2 | D27: Insert lines above here only | E27: [Mục đích] Kiểm tra hiệu năng mượt mà của Canvas và kiểm thử an toàn bảo mật hệ thống. [Điều kiện] Đăng nhập bằng tài khoản User thông thường. [Các bước] 1. Đo FPS khi thú cưng chuyển động trong 30 phút. 2. Nhập URL /admin/pets trên trình duyệt. 3. Thử inject payload <script>alert(1)</script> vào tên thú. [Kỳ vọng] FPS đạt 55-60 FPS ổn định, RAM không phình; route /admin bị chặn 403; payload XSS bị escape an toàn. | F27: Insert lines above here only | H27: Lead QA | J27: UC-10 | K27: Insert lines above here only | L27: Critical | M27: P1 - High
A29: Warning: Be careful adding/removing rows in the following section - these values are used for data validation | G29: PM | K29: feature | L29: Hông biết
A30: Test Case Status | D30: Classification A
A31: Not Started | D31: Critical
A32: In Progress | D32: Major
A33: Draft | D33: Minor
A34: Pending Approval | D34: Trivial
A35: Approved | D35: Classification 5
D36: Classification 6
D37: Classification 7
D38: Classification 8
D39: Classification 9
D40: Classification 10
A41: Test Case Owner | D41: Classification 11
A42: Nguyễn Đỉnh (123000431) | D42: Classification 12
A43: Hồ Tâm Phi Hùng (123000287) | D43: Classification 13
A44: Võ Lê Hoàng Nhã (123000311)
D45: Classification B
D46: P1 - High
D47: P2 - Medium
D48: P3 - Low
D49: P4 - Lowest
D50: Classification 5
...

Sheet Test Case Coverage Plan
C1: Include in Test Iteration:
A2: Test Case ID | B2: Test Case Name | C2: 1 | D2: 2 | E2: 3 | F2: 4 | G2: 5 | H2: Planned Lead Tester | I2: Comments
A3: ='Test Case List'!C2 | B3: ='Test Case List'!D2 | C3: Yes | D3: Yes | E3: Yes | F3: Yes | G3: Yes | H3: Nguyễn Đỉnh (123000431)
A4: ='Test Case List'!C3 | B4: ='Test Case List'!D3 | C4: Yes | D4: Yes | E4: Yes | F4: Yes | G4: Yes | H4: Nguyễn Đỉnh (123000431)
A5: ='Test Case List'!C4 | B5: ='Test Case List'!D4 | C5: No | D5: Yes | E5: Yes | F5: Yes | G5: Yes | H5: Nguyễn Đỉnh (123000431)
A6: ='Test Case List'!C5 | B6: ='Test Case List'!D5 | C6: Yes | D6: Yes | E6: Yes | F6: Yes | G6: Yes | H6: Hồ Tâm Phi Hùng (123000287)
A7: ='Test Case List'!C6 | B7: ='Test Case List'!D6 | C7: Yes | D7: Yes | E7: Yes | F7: Yes | G7: Yes | H7: Hồ Tâm Phi Hùng (123000287)
A8: ='Test Case List'!C7 | B8: ='Test Case List'!D7 | C8: No | D8: Yes | E8: Yes | F8: Yes | G8: Yes | H8: Hồ Tâm Phi Hùng (123000287)
A9: ='Test Case List'!C8 | B9: ='Test Case List'!D8 | C9: No | D9: Yes | E9: Yes | F9: Yes | G9: Yes | H9: Hồ Tâm Phi Hùng (123000287)
A10: ='Test Case List'!C9 | B10: ='Test Case List'!D9 | C10: No | D10: Yes | E10: Yes | F10: Yes | G10: Yes | H10: Nguyễn Đỉnh (123000431)
A11: ='Test Case List'!C10 | B11: ='Test Case List'!D10 | C11: No | D11: Yes | E11: Yes | F11: Yes | G11: Yes | H11: Nguyễn Đỉnh (123000431)
A12: ='Test Case List'!C11 | B12: ='Test Case List'!D11 | C12: Yes | D12: Yes | E12: Yes | F12: Yes | G12: Yes | H12: Võ Lê Hoàng Nhã (123000311)
A13: ='Test Case List'!C12 | B13: ='Test Case List'!D12 | C13: No | D13: Yes | E13: Yes | F13: Yes | G13: Yes | H13: Võ Lê Hoàng Nhã (123000311)
A14: ='Test Case List'!C13 | B14: ='Test Case List'!D13 | C14: No | D14: Yes | E14: Yes | F14: Yes | G14: Yes | H14: Võ Lê Hoàng Nhã (123000311)
A15: ='Test Case List'!C14 | B15: ='Test Case List'!D14 | C15: No | D15: No | E15: Yes | F15: Yes | G15: Yes | H15: Võ Lê Hoàng Nhã (123000311) | N15: Test Case Coverage Plan
A16: ='Test Case List'!C15 | B16: ='Test Case List'!D15 | C16: No | D16: No | E16: Yes | F16: Yes | G16: Yes | H16: Võ Lê Hoàng Nhã (123000311)
A17: ='Test Case List'!C16 | B17: ='Test Case List'!D16 | C17: Yes | D17: Yes | E17: Yes | F17: Yes | G17: Yes | H17: Hồ Tâm Phi Hùng (123000287)
A18: ='Test Case List'!C17 | B18: ='Test Case List'!D17 | C18: No | D18: No | E18: Yes | F18: Yes | G18: Yes | H18: Hồ Tâm Phi Hùng (123000287)
A19: ='Test Case List'!C18 | B19: ='Test Case List'!D18 | C19: No | D19: No | E19: Yes | F19: Yes | G19: Yes | H19: Võ Lê Hoàng Nhã (123000311)
A20: ='Test Case List'!C19 | B20: ='Test Case List'!D19 | C20: Yes | D20: Yes | E20: Yes | F20: Yes | G20: Yes | H20: Hồ Tâm Phi Hùng (123000287)
A21: ='Test Case List'!C20 | B21: ='Test Case List'!D20 | C21: No | D21: Yes | E21: Yes | F21: Yes | G21: Yes | H21: Hồ Tâm Phi Hùng (123000287)
A22: ='Test Case List'!C21 | B22: ='Test Case List'!D21 | C22: No | D22: Yes | E22: Yes | F22: Yes | G22: Yes | H22: Hồ Tâm Phi Hùng (123000287)
A23: ='Test Case List'!C22 | B23: ='Test Case List'!D22 | C23: Yes | D23: Yes | E23: Yes | F23: Yes | G23: Yes | H23: Nguyễn Đỉnh (123000431)
A24: ='Test Case List'!C23 | B24: ='Test Case List'!D23 | C24: Yes | D24: Yes | E24: Yes | F24: Yes | G24: Yes | H24: Nguyễn Đỉnh (123000431)
A25: ='Test Case List'!C24 | B25: ='Test Case List'!D24 | C25: Yes | D25: Yes | E25: Yes | F25: Yes | G25: Yes | H25: Nguyễn Đỉnh (123000431)
A26: ='Test Case List'!C25 | B26: ='Test Case List'!D25 | C26: Yes | D26: Yes | E26: Yes | F26: Yes | G26: Yes | H26: Nguyễn Đỉnh (123000431)
A27: ='Test Case List'!C26 | B27: ='Test Case List'!D26 | C27: Yes | D27: Yes | E27: Yes | F27: Yes | G27: Yes | H27: Nguyễn Đỉnh (123000431)
A28: Insert Lines Above Here Only | B28: ='Test Case List'!D27 | C28: Insert Lines Above Here Only | D28: Yes | E28: Yes | F28: Yes | G28: Yes
A30: Warning: Be careful adding/removing rows in the following section - these values are used for data validation
A31: Include in Test Iteration
A32: Pending
A33: Yes
A34: No
A40: Planned Tester
A41: Nguyễn Đỉnh (123000431)
A42: Hồ Tâm Phi Hùng (123000287)
A43: Võ Lê Hoàng Nhã (123000311)

Sheet Test Iteration 1
A1: Test Case ID | B1: Test Case Name | C1: In This Test Iteration? | D1: Tester | E1: Status | F1: Defects Identified | G1: Blocking Defect ID(s) | H1: Comments
A2: ='Test Case List'!C2 | B2: ='Test Case List'!D2 | C2: =VLOOKUP(A2,'Test Case Coverage Plan'!$A$3:$G$27,3,FALSE) | D2: Nguyễn Đỉnh (123000431) | E2: Not Run
A3: ='Test Case List'!C3 | B3: ='Test Case List'!D3 | C3: =VLOOKUP(A3,'Test Case Coverage Plan'!$A$3:$G$27,3,FALSE) | D3: Nguyễn Đỉnh (123000431) | E3: Not Run
A4: ='Test Case List'!C4 | B4: ='Test Case List'!D4 | C4: =VLOOKUP(A4,'Test Case Coverage Plan'!$A$3:$G$27,3,FALSE) | E4: N/A
A5: ='Test Case List'!C5 | B5: ='Test Case List'!D5 | C5: =VLOOKUP(A5,'Test Case Coverage Plan'!$A$3:$G$27,3,FALSE) | D5: Hồ Tâm Phi Hùng (123000287) | E5: Not Run
A6: ='Test Case List'!C6 | B6: ='Test Case List'!D6 | C6: =VLOOKUP(A6,'Test Case Coverage Plan'!$A$3:$G$27,3,FALSE) | D6: Hồ Tâm Phi Hùng (123000287) | E6: Not Run
A7: ='Test Case List'!C7 | B7: ='Test Case List'!D7 | C7: =VLOOKUP(A7,'Test Case Coverage Plan'!$A$3:$G$27,3,FALSE) | E7: N/A
A8: ='Test Case List'!C8 | B8: ='Test Case List'!D8 | C8: =VLOOKUP(A8,'Test Case Coverage Plan'!$A$3:$G$27,3,FALSE) | E8: N/A
A9: ='Test Case List'!C9 | B9: ='Test Case List'!D9 | C9: =VLOOKUP(A9,'Test Case Coverage Plan'!$A$3:$G$27,3,FALSE) | E9: N/A
A10: ='Test Case List'!C10 | B10: ='Test Case List'!D10 | C10: =VLOOKUP(A10,'Test Case Coverage Plan'!$A$3:$G$27,3,FALSE) | E10: N/A
A11: ='Test Case List'!C11 | B11: ='Test Case List'!D11 | C11: =VLOOKUP(A11,'Test Case Coverage Plan'!$A$3:$G$27,3,FALSE) | D11: Võ Lê Hoàng Nhã (123000311) | E11: Not Run
A12: ='Test Case List'!C12 | B12: ='Test Case List'!D12 | C12: =VLOOKUP(A12,'Test Case Coverage Plan'!$A$3:$G$27,3,FALSE) | E12: N/A
A13: ='Test Case List'!C13 | B13: ='Test Case List'!D13 | C13: =VLOOKUP(A13,'Test Case Coverage Plan'!$A$3:$G$27,3,FALSE) | E13: N/A
A14: ='Test Case List'!C14 | B14: ='Test Case List'!D14 | C14: =VLOOKUP(A14,'Test Case Coverage Plan'!$A$3:$G$27,3,FALSE) | E14: N/A
A15: ='Test Case List'!C15 | B15: ='Test Case List'!D15 | C15: =VLOOKUP(A15,'Test Case Coverage Plan'!$A$3:$G$27,3,FALSE) | E15: N/A
A16: ='Test Case List'!C16 | B16: ='Test Case List'!D16 | C16: =VLOOKUP(A16,'Test Case Coverage Plan'!$A$3:$G$27,3,FALSE) | D16: Hồ Tâm Phi Hùng (123000287) | E16: Not Run
A17: ='Test Case List'!C17 | B17: ='Test Case List'!D17 | C17: =VLOOKUP(A17,'Test Case Coverage Plan'!$A$3:$G$27,3,FALSE) | E17: N/A
A18: ='Test Case List'!C18 | B18: ='Test Case List'!D18 | C18: =VLOOKUP(A18,'Test Case Coverage Plan'!$A$3:$G$27,3,FALSE) | E18: N/A
A19: ='Test Case List'!C19 | B19: ='Test Case List'!D19 | C19: =VLOOKUP(A19,'Test Case Coverage Plan'!$A$3:$G$27,3,FALSE) | D19: Hồ Tâm Phi Hùng (123000287) | E19: Not Run
A20: ='Test Case List'!C20 | B20: ='Test Case List'!D20 | C20: =VLOOKUP(A20,'Test Case Coverage Plan'!$A$3:$G$27,3,FALSE) | E20: N/A
A21: ='Test Case List'!C21 | B21: ='Test Case List'!D21 | C21: =VLOOKUP(A21,'Test Case Coverage Plan'!$A$3:$G$27,3,FALSE) | E21: N/A
A22: ='Test Case List'!C22 | B22: ='Test Case List'!D22 | C22: =VLOOKUP(A22,'Test Case Coverage Plan'!$A$3:$G$27,3,FALSE) | D22: Nguyễn Đỉnh (123000431) | E22: Not Run
A23: ='Test Case List'!C23 | B23: ='Test Case List'!D23 | C23: =VLOOKUP(A23,'Test Case Coverage Plan'!$A$3:$G$27,3,FALSE) | D23: Nguyễn Đỉnh (123000431) | E23: Not Run
A24: ='Test Case List'!C24 | B24: ='Test Case List'!D24 | C24: =VLOOKUP(A24,'Test Case Coverage Plan'!$A$3:$G$27,3,FALSE) | D24: Nguyễn Đỉnh (123000431) | E24: Not Run
A25: ='Test Case List'!C25 | B25: ='Test Case List'!D25 | C25: =VLOOKUP(A25,'Test Case Coverage Plan'!$A$3:$G$27,3,FALSE) | D25: Nguyễn Đỉnh (123000431) | E25: Not Run
A26: ='Test Case List'!C26 | B26: ='Test Case List'!D26 | C26: =VLOOKUP(A26,'Test Case Coverage Plan'!$A$3:$G$27,3,FALSE) | D26: Nguyễn Đỉnh (123000431) | E26: Not Run
A27: Insert Rows Only Above Here | B27: ='Test Case List'!D27 | C27: =VLOOKUP(A27,'Test Case Coverage Plan'!$A$3:$G$27,3,FALSE) | D27: Insert Rows Only Above Here | E27: Not Run
A29: Warning: Be careful adding/removing rows in the following section - these values are used for data validation | F29: Ticket id
A30: Tester | D30: Test Case Status | G30: Test Iteration Name
A31: Nguyễn Đỉnh (123000431) | D31: N/A | G31: Iteration One
A32: Hồ Tâm Phi Hùng (123000287) | D32: Not Run
A33: Võ Lê Hoàng Nhã (123000311) | D33: Blocked
D34: In Progress
D35: Run - Passed
D36: Run - Failed

Sheet Test Iteration 2
A1: Test Case ID | B1: Test Case Name | C1: In This Test Iteration? | D1: Tester | E1: Status | F1: Defects Identified | G1: Blocking Defect ID | H1: Comments
A2: ='Test Case List'!C2 | B2: ='Test Case List'!D2 | C2: =VLOOKUP(A2,'Test Case Coverage Plan'!$A$3:$G$27,4,FALSE) | D2: Nguyễn Đỉnh (123000431) | E2: Not Run
A3: ='Test Case List'!C3 | B3: ='Test Case List'!D3 | C3: =VLOOKUP(A3,'Test Case Coverage Plan'!$A$3:$G$27,4,FALSE) | D3: Nguyễn Đỉnh (123000431) | E3: Not Run
A4: ='Test Case List'!C4 | B4: ='Test Case List'!D4 | C4: =VLOOKUP(A4,'Test Case Coverage Plan'!$A$3:$G$27,4,FALSE) | D4: Nguyễn Đỉnh (123000431) | E4: Not Run
A5: ='Test Case List'!C5 | B5: ='Test Case List'!D5 | C5: =VLOOKUP(A5,'Test Case Coverage Plan'!$A$3:$G$27,4,FALSE) | D5: Hồ Tâm Phi Hùng (123000287) | E5: Not Run
A6: ='Test Case List'!C6 | B6: ='Test Case List'!D6 | C6: =VLOOKUP(A6,'Test Case Coverage Plan'!$A$3:$G$27,4,FALSE) | D6: Hồ Tâm Phi Hùng (123000287) | E6: Not Run
A7: ='Test Case List'!C7 | B7: ='Test Case List'!D7 | C7: =VLOOKUP(A7,'Test Case Coverage Plan'!$A$3:$G$27,4,FALSE) | D7: Hồ Tâm Phi Hùng (123000287) | E7: Not Run
A8: ='Test Case List'!C8 | B8: ='Test Case List'!D8 | C8: =VLOOKUP(A8,'Test Case Coverage Plan'!$A$3:$G$27,4,FALSE) | D8: Hồ Tâm Phi Hùng (123000287) | E8: Not Run
A9: ='Test Case List'!C9 | B9: ='Test Case List'!D9 | C9: =VLOOKUP(A9,'Test Case Coverage Plan'!$A$3:$G$27,4,FALSE) | D9: Nguyễn Đỉnh (123000431) | E9: Not Run
A10: ='Test Case List'!C10 | B10: ='Test Case List'!D10 | C10: =VLOOKUP(A10,'Test Case Coverage Plan'!$A$3:$G$27,4,FALSE) | D10: Nguyễn Đỉnh (123000431) | E10: Not Run
A11: ='Test Case List'!C11 | B11: ='Test Case List'!D11 | C11: =VLOOKUP(A11,'Test Case Coverage Plan'!$A$3:$G$27,4,FALSE) | D11: Võ Lê Hoàng Nhã (123000311) | E11: Not Run
A12: ='Test Case List'!C12 | B12: ='Test Case List'!D12 | C12: =VLOOKUP(A12,'Test Case Coverage Plan'!$A$3:$G$27,4,FALSE) | D12: Võ Lê Hoàng Nhã (123000311) | E12: Not Run
A13: ='Test Case List'!C13 | B13: ='Test Case List'!D13 | C13: =VLOOKUP(A13,'Test Case Coverage Plan'!$A$3:$G$27,4,FALSE) | D13: Võ Lê Hoàng Nhã (123000311) | E13: Not Run
A14: ='Test Case List'!C14 | B14: ='Test Case List'!D14 | C14: =VLOOKUP(A14,'Test Case Coverage Plan'!$A$3:$G$27,4,FALSE) | E14: N/A
A15: ='Test Case List'!C15 | B15: ='Test Case List'!D15 | C15: =VLOOKUP(A15,'Test Case Coverage Plan'!$A$3:$G$27,4,FALSE) | E15: N/A
A16: ='Test Case List'!C16 | B16: ='Test Case List'!D16 | C16: =VLOOKUP(A16,'Test Case Coverage Plan'!$A$3:$G$27,4,FALSE) | D16: Hồ Tâm Phi Hùng (123000287) | E16: Not Run
A17: ='Test Case List'!C17 | B17: ='Test Case List'!D17 | C17: =VLOOKUP(A17,'Test Case Coverage Plan'!$A$3:$G$27,4,FALSE) | E17: N/A
A18: ='Test Case List'!C18 | B18: ='Test Case List'!D18 | C18: =VLOOKUP(A18,'Test Case Coverage Plan'!$A$3:$G$27,4,FALSE) | E18: N/A
A19: ='Test Case List'!C19 | B19: ='Test Case List'!D19 | C19: =VLOOKUP(A19,'Test Case Coverage Plan'!$A$3:$G$27,4,FALSE) | D19: Hồ Tâm Phi Hùng (123000287) | E19: Not Run
A20: ='Test Case List'!C20 | B20: ='Test Case List'!D20 | C20: =VLOOKUP(A20,'Test Case Coverage Plan'!$A$3:$G$27,4,FALSE) | D20: Hồ Tâm Phi Hùng (123000287) | E20: Not Run
A21: ='Test Case List'!C21 | B21: ='Test Case List'!D21 | C21: =VLOOKUP(A21,'Test Case Coverage Plan'!$A$3:$G$27,4,FALSE) | D21: Hồ Tâm Phi Hùng (123000287) | E21: Not Run
A22: ='Test Case List'!C22 | B22: ='Test Case List'!D22 | C22: =VLOOKUP(A22,'Test Case Coverage Plan'!$A$3:$G$27,4,FALSE) | D22: Nguyễn Đỉnh (123000431) | E22: Not Run
A23: ='Test Case List'!C23 | B23: ='Test Case List'!D23 | C23: =VLOOKUP(A23,'Test Case Coverage Plan'!$A$3:$G$27,4,FALSE) | D23: Nguyễn Đỉnh (123000431) | E23: Not Run
A24: ='Test Case List'!C24 | B24: ='Test Case List'!D24 | C24: =VLOOKUP(A24,'Test Case Coverage Plan'!$A$3:$G$27,4,FALSE) | D24: Nguyễn Đỉnh (123000431) | E24: Not Run
A25: ='Test Case List'!C25 | B25: ='Test Case List'!D25 | C25: =VLOOKUP(A25,'Test Case Coverage Plan'!$A$3:$G$27,4,FALSE) | D25: Nguyễn Đỉnh (123000431) | E25: Not Run
A26: ='Test Case List'!C26 | B26: ='Test Case List'!D26 | C26: =VLOOKUP(A26,'Test Case Coverage Plan'!$A$3:$G$27,4,FALSE) | D26: Nguyễn Đỉnh (123000431) | E26: Not Run
A27: Insert Rows Only Above Here | B27: ='Test Case List'!D27 | C27: =VLOOKUP(A27,'Test Case Coverage Plan'!$A$3:$G$27,4,FALSE) | D27: Insert Rows Only Above Here | E27: Not Run
A29: Warning: Be careful adding/removing rows in the following section - these values are used for data validation
A30: Tester | D30: Test Case Status | G30: Test Iteration Name
A31: Nguyễn Đỉnh (123000431) | D31: N/A | G31: Iteration Two
A32: Hồ Tâm Phi Hùng (123000287) | D32: Not Run
A33: Võ Lê Hoàng Nhã (123000311) | D33: Blocked
D34: In Progress
D35: Run - Passed
D36: Run - Failed

Sheet Test Iteration 3
A1: Test Case ID | B1: Test Case Name | C1: In This Test Iteration? | D1: Tester | E1: Status | F1: Defects Identified | G1: Blocking Defect ID | H1: Comments
A2: ='Test Case List'!C2 | B2: ='Test Case List'!D2 | C2: =VLOOKUP(A2,'Test Case Coverage Plan'!$A$3:$G$27,5,FALSE) | D2: Nguyễn Đỉnh (123000431) | E2: Not Run
A3: ='Test Case List'!C3 | B3: ='Test Case List'!D3 | C3: =VLOOKUP(A3,'Test Case Coverage Plan'!$A$3:$G$27,5,FALSE) | D3: Nguyễn Đỉnh (123000431) | E3: Not Run
A4: ='Test Case List'!C4 | B4: ='Test Case List'!D4 | C4: =VLOOKUP(A4,'Test Case Coverage Plan'!$A$3:$G$27,5,FALSE) | D4: Nguyễn Đỉnh (123000431) | E4: Not Run
A5: ='Test Case List'!C5 | B5: ='Test Case List'!D5 | C5: =VLOOKUP(A5,'Test Case Coverage Plan'!$A$3:$G$27,5,FALSE) | D5: Hồ Tâm Phi Hùng (123000287) | E5: Not Run
A6: ='Test Case List'!C6 | B6: ='Test Case List'!D6 | C6: =VLOOKUP(A6,'Test Case Coverage Plan'!$A$3:$G$27,5,FALSE) | D6: Hồ Tâm Phi Hùng (123000287) | E6: Not Run
A7: ='Test Case List'!C7 | B7: ='Test Case List'!D7 | C7: =VLOOKUP(A7,'Test Case Coverage Plan'!$A$3:$G$27,5,FALSE) | D7: Hồ Tâm Phi Hùng (123000287) | E7: Not Run
A8: ='Test Case List'!C8 | B8: ='Test Case List'!D8 | C8: =VLOOKUP(A8,'Test Case Coverage Plan'!$A$3:$G$27,5,FALSE) | D8: Hồ Tâm Phi Hùng (123000287) | E8: Not Run
A9: ='Test Case List'!C9 | B9: ='Test Case List'!D9 | C9: =VLOOKUP(A9,'Test Case Coverage Plan'!$A$3:$G$27,5,FALSE) | D9: Nguyễn Đỉnh (123000431) | E9: Not Run
A10: ='Test Case List'!C10 | B10: ='Test Case List'!D10 | C10: =VLOOKUP(A10,'Test Case Coverage Plan'!$A$3:$G$27,5,FALSE) | D10: Nguyễn Đỉnh (123000431) | E10: Not Run
A11: ='Test Case List'!C11 | B11: ='Test Case List'!D11 | C11: =VLOOKUP(A11,'Test Case Coverage Plan'!$A$3:$G$27,5,FALSE) | D11: Võ Lê Hoàng Nhã (123000311) | E11: Not Run
A12: ='Test Case List'!C12 | B12: ='Test Case List'!D12 | C12: =VLOOKUP(A12,'Test Case Coverage Plan'!$A$3:$G$27,5,FALSE) | D12: Võ Lê Hoàng Nhã (123000311) | E12: Not Run
A13: ='Test Case List'!C13 | B13: ='Test Case List'!D13 | C13: =VLOOKUP(A13,'Test Case Coverage Plan'!$A$3:$G$27,5,FALSE) | D13: Võ Lê Hoàng Nhã (123000311) | E13: Not Run
... A26: ='Test Case List'!C26 | B26: ='Test Case List'!D26 | C26: =VLOOKUP(A26,'Test Case Coverage Plan'!$A$3:$G$27,5,FALSE) | D26: Nguyễn Đỉnh (123000431) | E26: Not Run
A27: Insert Rows Only Above Here | B27: ='Test Case List'!D27 | C27: =VLOOKUP(A27,'Test Case Coverage Plan'!$A$3:$G$27,5,FALSE) | D27: Insert Rows Only Above Here | E27: Not Run
A29: Warning: Be careful adding/removing rows in the following section - these values are used for data validation
A30: Tester | D30: Test Case Status | G30: Test Iteration Name
A31: Nguyễn Đỉnh (123000431) | D31: Not Run | G31: Iteration Three
A32: Hồ Tâm Phi Hùng (123000287) | D32: Blocked
A33: Võ Lê Hoàng Nhã (123000311) | D33: In Progress
D34: Run - Passed
D35: Run - Failed

Sheet Test Iteration 4
A1: Test Case ID | B1: Test Case Name | C1: In This Test Iteration? | D1: Tester | E1: Status | F1: Defects Identified | G1: Blocking Defect ID | H1: Comments
A2: ='Test Case List'!C2 | B2: ='Test Case List'!D2 | C2: =VLOOKUP(A2,'Test Case Coverage Plan'!$A$3:$G$27,6,FALSE) | D2: Nguyễn Đỉnh (123000431) | E2: Not Run
A3: ='Test Case List'!C3 | B3: ='Test Case List'!D3 | C3: =VLOOKUP(A3,'Test Case Coverage Plan'!$A$3:$G$27,6,FALSE) | D3: Nguyễn Đỉnh (123000431) | E3: Not Run
A4: ='Test Case List'!C4 | B4: ='Test Case List'!D4 | C4: =VLOOKUP(A4,'Test Case Coverage Plan'!$A$3:$G$27,6,FALSE) | D4: Nguyễn Đỉnh (123000431) | E4: Not Run
A5: ='Test Case List'!C5 | B5: ='Test Case List'!D5 | C5: =VLOOKUP(A5,'Test Case Coverage Plan'!$A$3:$G$27,6,FALSE) | D5: Hồ Tâm Phi Hùng (123000287) | E5: Not Run
A6: ='Test Case List'!C6 | B6: ='Test Case List'!D6 | C6: =VLOOKUP(A6,'Test Case Coverage Plan'!$A$3:$G$27,6,FALSE) | D6: Hồ Tâm Phi Hùng (123000287) | E6: Not Run
A7: ='Test Case List'!C7 | B7: ='Test Case List'!D7 | C7: =VLOOKUP(A7,'Test Case Coverage Plan'!$A$3:$G$27,6,FALSE) | D7: Hồ Tâm Phi Hùng (123000287) | E7: Not Run
A8: ='Test Case List'!C8 | B8: ='Test Case List'!D8 | C8: =VLOOKUP(A8,'Test Case Coverage Plan'!$A$3:$G$27,6,FALSE) | D8: Hồ Tâm Phi Hùng (123000287) | E8: Not Run
A9: ='Test Case List'!C9 | B9: ='Test Case List'!D9 | C9: =VLOOKUP(A9,'Test Case Coverage Plan'!$A$3:$G$27,6,FALSE) | D9: Nguyễn Đỉnh (123000431) | E9: Not Run
A10: ='Test Case List'!C10 | B10: ='Test Case List'!D10 | C10: =VLOOKUP(A10,'Test Case Coverage Plan'!$A$3:$G$27,6,FALSE) | D10: Nguyễn Đỉnh (123000431) | E10: Not Run
A11: ='Test Case List'!C11 | B11: ='Test Case List'!D11 | C11: =VLOOKUP(A11,'Test Case Coverage Plan'!$A$3:$G$27,6,FALSE) | D11: Võ Lê Hoàng Nhã (123000311) | E11: Not Run
A12: ='Test Case List'!C12 | B12: ='Test Case List'!D12 | C12: =VLOOKUP(A12,'Test Case Coverage Plan'!$A$3:$G$27,6,FALSE) | D12: Võ Lê Hoàng Nhã (123000311) | E12: Not Run
A13: ='Test Case List'!C13 | B13: ='Test Case List'!D13 | C13: =VLOOKUP(A13,'Test Case Coverage Plan'!$A$3:$G$27,6,FALSE) | D13: Võ Lê Hoàng Nhã (123000311) | E13: Not Run
... A26: ='Test Case List'!C26 | B26: ='Test Case List'!D26 | C26: =VLOOKUP(A26,'Test Case Coverage Plan'!$A$3:$G$27,6,FALSE) | D26: Nguyễn Đỉnh (123000431) | E26: Not Run
A27: Insert Rows Only Above Here | B27: ='Test Case List'!D27 | C27: =VLOOKUP(A27,'Test Case Coverage Plan'!$A$3:$G$27,6,FALSE) | D27: Insert Rows Only Above Here | E27: Not Run
A29: Warning: Be careful adding/removing rows in the following section - these values are used for data validation
A30: Tester | D30: Test Case Status | G30: Test Iteration Name
A31: Nguyễn Đỉnh (123000431) | D31: N/A | G31: Iteration Four
A32: Hồ Tâm Phi Hùng (123000287) | D32: Not Run
A33: Võ Lê Hoàng Nhã (123000311) | D33: Blocked
D34: In Progress
D35: Run - Passed
D36: Run - Failed

Sheet Test Iteration 5
A1: Test Case ID | B1: Test Case Name | C1: In This Test Iteration? | D1: Tester | E1: Status | F1: Defects Identified | G1: Blocking Defect ID | H1: Comments
A2: ='Test Case List'!C2 | B2: ='Test Case List'!D2 | C2: =VLOOKUP(A2,'Test Case Coverage Plan'!$A$3:$G$27,7,FALSE) | D2: Nguyễn Đỉnh (123000431) | E2: Not Run
A3: ='Test Case List'!C3 | B3: ='Test Case List'!D3 | C3: =VLOOKUP(A3,'Test Case Coverage Plan'!$A$3:$G$27,7,FALSE) | D3: Nguyễn Đỉnh (123000431) | E3: Not Run
A4: ='Test Case List'!C4 | B4: ='Test Case List'!D4 | C4: =VLOOKUP(A4,'Test Case Coverage Plan'!$A$3:$G$27,7,FALSE) | D4: Nguyễn Đỉnh (123000431) | E4: Not Run
A5: ='Test Case List'!C5 | B5: ='Test Case List'!D5 | C5: =VLOOKUP(A5,'Test Case Coverage Plan'!$A$3:$G$27,7,FALSE) | D5: Hồ Tâm Phi Hùng (123000287) | E5: Not Run
A6: ='Test Case List'!C6 | B6: ='Test Case List'!D6 | C6: =VLOOKUP(A6,'Test Case Coverage Plan'!$A$3:$G$27,7,FALSE) | D6: Hồ Tâm Phi Hùng (123000287) | E6: Not Run
A7: ='Test Case List'!C7 | B7: ='Test Case List'!D7 | C7: =VLOOKUP(A7,'Test Case Coverage Plan'!$A$3:$G$27,7,FALSE) | D7: Hồ Tâm Phi Hùng (123000287) | E7: Not Run
A8: ='Test Case List'!C8 | B8: ='Test Case List'!D8 | C8: =VLOOKUP(A8,'Test Case Coverage Plan'!$A$3:$G$27,7,FALSE) | D8: Hồ Tâm Phi Hùng (123000287) | E8: Not Run
A9: ='Test Case List'!C9 | B9: ='Test Case List'!D9 | C9: =VLOOKUP(A9,'Test Case Coverage Plan'!$A$3:$G$27,7,FALSE) | D9: Nguyễn Đỉnh (123000431) | E9: Not Run
A10: ='Test Case List'!C10 | B10: ='Test Case List'!D10 | C10: =VLOOKUP(A10,'Test Case Coverage Plan'!$A$3:$G$27,7,FALSE) | D10: Nguyễn Đỉnh (123000431) | E10: Not Run
A11: ='Test Case List'!C11 | B11: ='Test Case List'!D11 | C11: =VLOOKUP(A11,'Test Case Coverage Plan'!$A$3:$G$27,7,FALSE) | D11: Võ Lê Hoàng Nhã (123000311) | E11: Not Run
A12: ='Test Case List'!C12 | B12: ='Test Case List'!D12 | C12: =VLOOKUP(A12,'Test Case Coverage Plan'!$A$3:$G$27,7,FALSE) | D12: Võ Lê Hoàng Nhã (123000311) | E12: Not Run
A13: ='Test Case List'!C13 | B13: ='Test Case List'!D13 | C13: =VLOOKUP(A13,'Test Case Coverage Plan'!$A$3:$G$27,7,FALSE) | D13: Võ Lê Hoàng Nhã (123000311) | E13: Not Run
... A26: ='Test Case List'!C26 | B26: ='Test Case List'!D26 | C26: =VLOOKUP(A26,'Test Case Coverage Plan'!$A$3:$G$27,7,FALSE) | D26: Nguyễn Đỉnh (123000431) | E26: Not Run
A27: Insert Rows Only Above Here | B27: ='Test Case List'!D27 | C27: =VLOOKUP(A27,'Test Case Coverage Plan'!$A$3:$G$27,7,FALSE) | D27: Insert Rows Only Above Here | E27: Not Run
A29: Warning: Be careful adding/removing rows in the following section - these values are used for data validation
A30: Tester | D30: Test Case Status | G30: Test Iteration Name
A31: Nguyễn Đỉnh (123000431) | D31: N/A | G31: Iteration Five
A32: Hồ Tâm Phi Hùng (123000287) | D32: Not Run
A33: Võ Lê Hoàng Nhã (123000311) | D33: Blocked
D34: In Progress
D35: Run - Passed
D36: Run - Failed

Sheet Stats
A1: Test Case ID | B1: Test Case Name | C1: Iteration | D1: In This Iteration? | E1: Tester | F1: Status | G1: Classification A | H1: Classification B
A2: ='Test Iteration 1'!A2 | B2: ='Test Iteration 1'!B2 | C2: ='Test Iteration 1'!$G$31 | D2: ='Test Iteration 1'!C2 | E2: ='Test Iteration 1'!D2 | F2: ='Test Iteration 1'!E2 | G2: ='Test Case List'!L2 | H2: ='Test Case List'!M2
A3: ='Test Iteration 1'!A3 | B3: ='Test Iteration 1'!B3 | C3: ='Test Iteration 1'!$G$31 | D3: ='Test Iteration 1'!C3 | E3: ='Test Iteration 1'!D3 | F3: ='Test Iteration 1'!E3 | G3: ='Test Case List'!L3 | H3: ='Test Case List'!M3
A4: ='Test Iteration 1'!A4 | B4: ='Test Iteration 1'!B4 | C4: ='Test Iteration 1'!$G$31 | D4: ='Test Iteration 1'!C4 | E4: ='Test Iteration 1'!D4 | F4: ='Test Iteration 1'!E4 | G4: ='Test Case List'!L4 | H4: ='Test Case List'!M4
A5: ='Test Iteration 1'!A5 | B5: ='Test Iteration 1'!B5 | C5: ='Test Iteration 1'!$G$31 | D5: ='Test Iteration 1'!C5 | E5: ='Test Iteration 1'!D5 | F5: ='Test Iteration 1'!E5 | G5: ='Test Case List'!L5 | H5: ='Test Case List'!M5
A6: ='Test Iteration 1'!A6 | B6: ='Test Iteration 1'!B6 | C6: ='Test Iteration 1'!$G$31 | D6: ='Test Iteration 1'!C6 | E6: ='Test Iteration 1'!D6 | F6: ='Test Iteration 1'!E6 | G6: ='Test Case List'!L6 | H6: ='Test Case List'!M6
A7: ='Test Iteration 1'!A7 | B7: ='Test Iteration 1'!B7 | C7: ='Test Iteration 1'!$G$31 | D7: ='Test Iteration 1'!C7 | E7: ='Test Iteration 1'!D7 | F7: ='Test Iteration 1'!E7 | G7: ='Test Case List'!L7 | H7: ='Test Case List'!M7
A8: ='Test Iteration 1'!A8 | B8: ='Test Iteration 1'!B8 | C8: ='Test Iteration 1'!$G$31 | D8: ='Test Iteration 1'!C8 | E8: ='Test Iteration 1'!D8 | F8: ='Test Iteration 1'!E8 | G8: ='Test Case List'!L8 | H8: ='Test Case List'!M8
A9: ='Test Iteration 1'!A9 | B9: ='Test Iteration 1'!B9 | C9: ='Test Iteration 1'!$G$31 | D9: ='Test Iteration 1'!C9 | E9: ='Test Iteration 1'!D9 | F9: ='Test Iteration 1'!E9 | G9: ='Test Case List'!L9 | H9: ='Test Case List'!M9
A10: ='Test Iteration 1'!A10 | B10: ='Test Iteration 1'!B10 | C10: ='Test Iteration 1'!$G$31 | D10: ='Test Iteration 1'!C10 | E10: ='Test Iteration 1'!D10 | F10: ='Test Iteration 1'!E10 | G10: ='Test Case List'!L10 | H10: ='Test Case List'!M10
A11: ='Test Iteration 1'!A11 | B11: ='Test Iteration 1'!B11 | C11: ='Test Iteration 1'!$G$31 | D11: ='Test Iteration 1'!C11 | E11: ='Test Iteration 1'!D11 | F11: ='Test Iteration 1'!E11 | G11: ='Test Case List'!L11 | H11: ='Test Case List'!M11
A12: ='Test Iteration 1'!A12 | B12: ='Test Iteration 1'!B12 | C12: ='Test Iteration 1'!$G$31 | D12: ='Test Iteration 1'!C12 | E12: ='Test Iteration 1'!D12 | F12: ='Test Iteration 1'!E12 | G12: ='Test Case List'!L12 | H12: ='Test Case List'!M12
A13: ='Test Iteration 1'!A13 | B13: ='Test Iteration 1'!B13 | C13: ='Test Iteration 1'!$G$31 | D13: ='Test Iteration 1'!C13 | E13: ='Test Iteration 1'!D13 | F13: ='Test Iteration 1'!E13 | G13: ='Test Case List'!L13 | H13: ='Test Case List'!M13
... A26: ='Test Iteration 1'!A26 | B26: ='Test Iteration 1'!B26 | C26: ='Test Iteration 1'!$G$31 | D26: ='Test Iteration 1'!C26 | E26: ='Test Iteration 1'!D26 | F26: ='Test Iteration 1'!E26 | G26: ='Test Case List'!L26 | H26: ='Test Case List'!M26
A27: ='Test Iteration 2'!A2 | B27: ='Test Iteration 2'!B2 | C27: ='Test Iteration 2'!$G$31 | D27: ='Test Iteration 2'!C2 | E27: ='Test Iteration 2'!D2 | F27: ='Test Iteration 2'!E2 | G27: ='Test Case List'!L2 | H27: ='Test Case List'!M2
A28: ='Test Iteration 2'!A3 | B28: ='Test Iteration 2'!B3 | C28: ='Test Iteration 2'!$G$31 | D28: ='Test Iteration 2'!C3 | E28: ='Test Iteration 2'!D3 | F28: ='Test Iteration 2'!E3 | G28: ='Test Case List'!L3 | H28: ='Test Case List'!M3
A29: ='Test Iteration 2'!A4 | B29: ='Test Iteration 2'!B4 | C29: ='Test Iteration 2'!$G$31 | D29: ='Test Iteration 2'!C4 | E29: ='Test Iteration 2'!D4 | F29: ='Test Iteration 2'!E4 | G29: ='Test Case List'!L4 | H29: ='Test Case List'!M4
A30: ='Test Iteration 2'!A5 | B30: ='Test Iteration 2'!B5 | C30: ='Test Iteration 2'!$G$31 | D30: ='Test Iteration 2'!C5 | E30: ='Test Iteration 2'!D5 | F30: ='Test Iteration 2'!E5 | G30: ='Test Case List'!L5 | H30: ='Test Case List'!M5
A31: ='Test Iteration 2'!A6 | B31: ='Test Iteration 2'!B6 | C31: ='Test Iteration 2'!$G$31 | D31: ='Test Iteration 2'!C6 | E31: ='Test Iteration 2'!D6 | F31: ='Test Iteration 2'!E6 | G31: ='Test Case List'!L6 | H31: ='Test Case List'!M6
A32: ='Test Iteration 2'!A7 | B32: ='Test Iteration 2'!B7 | C32: ='Test Iteration 2'!$G$31 | D32: ='Test Iteration 2'!C7 | E32: ='Test Iteration 2'!D7 | F32: ='Test Iteration 2'!E7 | G32: ='Test Case List'!L7 | H32: ='Test Case List'!M7
A33: ='Test Iteration 2'!A8 | B33: ='Test Iteration 2'!B8 | C33: ='Test Iteration 2'!$G$31 | D33: ='Test Iteration 2'!C8 | E33: ='Test Iteration 2'!D8 | F33: ='Test Iteration 2'!E8 | G33: ='Test Case List'!L8 | H33: ='Test Case List'!M8
A34: ='Test Iteration 2'!A9 | B34: ='Test Iteration 2'!B9 | C34: ='Test Iteration 2'!$G$31 | D34: ='Test Iteration 2'!C9 | E34: ='Test Iteration 2'!D9 | F34: ='Test Iteration 2'!E9 | G34: ='Test Case List'!L9 | H34: ='Test Case List'!M9
A35: ='Test Iteration 2'!A10 | B35: ='Test Iteration 2'!B10 | C35: ='Test Iteration 2'!$G$31 | D35: ='Test Iteration 2'!C10 | E35: ='Test Iteration 2'!D10 | F35: ='Test Iteration 2'!E10 | G35: ='Test Case List'!L10 | H35: ='Test Case List'!M10
A36: ='Test Iteration 2'!A11 | B36: ='Test Iteration 2'!B11 | C36: ='Test Iteration 2'!$G$31 | D36: ='Test Iteration 2'!C11 | E36: ='Test Iteration 2'!D11 | F36: ='Test Iteration 2'!E11 | G36: ='Test Case List'!L11 | H36: ='Test Case List'!M11
A37: ='Test Iteration 2'!A12 | B37: ='Test Iteration 2'!B12 | C37: ='Test Iteration 2'!$G$31 | D37: ='Test Iteration 2'!C12 | E37: ='Test Iteration 2'!D12 | F37: ='Test Iteration 2'!E12 | G37: ='Test Case List'!L12 | H37: ='Test Case List'!M12
A38: ='Test Iteration 2'!A13 | B38: ='Test Iteration 2'!B13 | C38: ='Test Iteration 2'!$G$31 | D38: ='Test Iteration 2'!C13 | E38: ='Test Iteration 2'!D13 | F38: ='Test Iteration 2'!E13 | G38: ='Test Case List'!L13 | H38: ='Test Case List'!M13
... A51: ='Test Iteration 2'!A26 | B51: ='Test Iteration 2'!B26 | C51: ='Test Iteration 2'!$G$31 | D51: ='Test Iteration 2'!C26 | E51: ='Test Iteration 2'!D26 | F51: ='Test Iteration 2'!E26 | G51: ='Test Case List'!L26 | H51: ='Test Case List'!M26
A52: ='Test Iteration 3'!A2 | B52: ='Test Iteration 3'!B2 | C52: ='Test Iteration 3'!$G$31 | D52: ='Test Iteration 3'!C2 | E52: ='Test Iteration 3'!D2 | F52: ='Test Iteration 3'!E2 | G52: ='Test Case List'!L2 | H52: ='Test Case List'!M2
A53: ='Test Iteration 3'!A3 | B53: ='Test Iteration 3'!B3 | C53: ='Test Iteration 3'!$G$31 | D53: ='Test Iteration 3'!C3 | E53: ='Test Iteration 3'!D3 | F53: ='Test Iteration 3'!E3 | G53: ='Test Case List'!L3 | H53: ='Test Case List'!M3
A54: ='Test Iteration 3'!A4 | B54: ='Test Iteration 3'!B4 | C54: ='Test Iteration 3'!$G$31 | D54: ='Test Iteration 3'!C4 | E54: ='Test Iteration 3'!D4 | F54: ='Test Iteration 3'!E4 | G54: ='Test Case List'!L4 | H54: ='Test Case List'!M4
A55: ='Test Iteration 3'!A5 | B55: ='Test Iteration 3'!B5 | C55: ='Test Iteration 3'!$G$31 | D55: ='Test Iteration 3'!C5 | E55: ='Test Iteration 3'!D5 | F55: ='Test Iteration 3'!E5 | G55: ='Test Case List'!L5 | H55: ='Test Case List'!M5
A56: ='Test Iteration 3'!A6 | B56: ='Test Iteration 3'!B6 | C56: ='Test Iteration 3'!$G$31 | D56: ='Test Iteration 3'!C6 | E56: ='Test Iteration 3'!D6 | F56: ='Test Iteration 3'!E6 | G56: ='Test Case List'!L6 | H56: ='Test Case List'!M6
A57: ='Test Iteration 3'!A7 | B57: ='Test Iteration 3'!B7 | C57: ='Test Iteration 3'!$G$31 | D57: ='Test Iteration 3'!C7 | E57: ='Test Iteration 3'!D7 | F57: ='Test Iteration 3'!E7 | G57: ='Test Case List'!L7 | H57: ='Test Case List'!M7
A58: ='Test Iteration 3'!A8 | B58: ='Test Iteration 3'!B8 | C58: ='Test Iteration 3'!$G$31 | D58: ='Test Iteration 3'!C8 | E58: ='Test Iteration 3'!D8 | F58: ='Test Iteration 3'!E8 | G58: ='Test Case List'!L8 | H58: ='Test Case List'!M8
A59: ='Test Iteration 3'!A9 | B59: ='Test Iteration 3'!B9 | C59: ='Test Iteration 3'!$G$31 | D59: ='Test Iteration 3'!C9 | E59: ='Test Iteration 3'!D9 | F59: ='Test Iteration 3'!E9 | G59: ='Test Case List'!L9 | H59: ='Test Case List'!M9
A60: ='Test Iteration 3'!A10 | B60: ='Test Iteration 3'!B10 | C60: ='Test Iteration 3'!$G$31 | D60: ='Test Iteration 3'!C10 | E60: ='Test Iteration 3'!D10 | F60: ='Test Iteration 3'!E10 | G60: ='Test Case List'!L10 | H60: ='Test Case List'!M10
A61: ='Test Iteration 3'!A11 | B61: ='Test Iteration 3'!B11 | C61: ='Test Iteration 3'!$G$31 | D61: ='Test Iteration 3'!C11 | E61: ='Test Iteration 3'!D11 | F61: ='Test Iteration 3'!E11 | G61: ='Test Case List'!L11 | H61: ='Test Case List'!M11
A62: ='Test Iteration 3'!A12 | B62: ='Test Iteration 3'!B12 | C62: ='Test Iteration 3'!$G$31 | D62: ='Test Iteration 3'!C12 | E62: ='Test Iteration 3'!D12 | F62: ='Test Iteration 3'!E12 | G62: ='Test Case List'!L12 | H62: ='Test Case List'!M12
A63: ='Test Iteration 3'!A13 | B63: ='Test Iteration 3'!B13 | C63: ='Test Iteration 3'!$G$31 | D63: ='Test Iteration 3'!C13 | E63: ='Test Iteration 3'!D13 | F63: ='Test Iteration 3'!E13 | G63: ='Test Case List'!L13 | H63: ='Test Case List'!M13
... A76: ='Test Iteration 3'!A26 | B76: ='Test Iteration 3'!B26 | C76: ='Test Iteration 3'!$G$31 | D76: ='Test Iteration 3'!C26 | E76: ='Test Iteration 3'!D26 | F76: ='Test Iteration 3'!E26 | G76: ='Test Case List'!L26 | H76: ='Test Case List'!M26
...

Sheet Pivot Tables
A1: Status by Iteration
A2: In This Iteration? | B2: Yes
A4: Count of Test Case ID | B4: Iteration
A5: Status | B5: Iteration Five | C5: Iteration Four | D5: Iteration One | E5: Iteration Two | F5: Iteration Three | G5: Grand Total
A6: Blocked | D6: 2 | E6: 3 | F6: 3 | G6: 8
A7: In Progress | F7: 3 | G7: 3
A8: Not Run | B8: 25 | C8: 22 | F8: 1 | G8: 48
A9: Run - Failed | D9: 1 | E9: 4 | F9: 6 | G9: 11
A10: Run - Passed | D10: 3 | E10: 6 | F10: 6 | G10: 15
A11: Grand Total | B11: 25 | C11: 22 | D11: 6 | E11: 13 | F11: 19 | G11: 85
A17: Test Case Status by Iteration
A18: Iteration | B18: Iteration Three
A19: In This Iteration? | B19: Yes
A21: Count of Test Case ID | B21: Status
A22: Test Case ID | B22: Blocked | C22: In Progress | D22: Not Run | E22: Run - Failed | F22: Run - Passed | G22: Grand Total
A23: TC1.1 | F23: 1 | G23: 1
A24: TC1.2 | F24: 1 | G24: 1
A25: TC1.3 | F25: 1 | G25: 1
A26: TC1.4 | F26: 1 | G26: 1
A27: TC2.1 | B27: 1 | G27: 1
A28: TC2.2 | E28: 1 | G28: 1
A29: TC3.1 | E29: 1 | G29: 1
A30: TC3.2 | E30: 1 | G30: 1
A31: TC3.3 | B31: 1 | G31: 1
A32: TC3.4 | F32: 1 | G32: 1
A33: TC3.5 | B33: 1 | G33: 1
A34: TC4.1 | F34: 1 | G34: 1
A35: TC4.10 | D35: 1 | G35: 1
A36: TC4.3 | E36: 1 | G36: 1
A37: TC4.4 | E37: 1 | G37: 1
A38: TC4.5 | C38: 1 | G38: 1
A39: TC4.6 | C39: 1 | G39: 1
A40: TC4.8 | E40: 1 | G40: 1
A41: TC4.9 | C41: 1 | G41: 1
A42: Grand Total | B42: 3 | C42: 3 | D42: 1 | E42: 6 | F42: 6 | G42: 19
A54: Classification A Status by Iteration
A55: Iteration | B55: Iteration One
A56: In This Iteration? | B56: Yes
A58: Count of Test Case ID | B58: Status
A59: Classification A | B59: Blocked | C59: Run - Failed | D59: Run - Passed | E59: Grand Total
...
